<?xml version="1.0" encoding="UTF-8"?>
<!-- Generated by org.testng.reporters.JUnitXMLReporter -->
<testsuite ignored="0" hostname="PQA-0591LT" failures="1" tests="4" name="Test8" time="32.497" errors="0" timestamp="2023-09-25T14:38:08 EDT">
  <testcase classname="com.obsqura.tests.CreateContact" name="CreateContactTest" time="4.765">
    <skipped/>
  </testcase> <!-- CreateContactTest -->
  <testcase classname="com.obsqura.tests.CreateContact" name="CreateContactTest" time="4.523">
    <skipped/>
  </testcase> <!-- CreateContactTest -->
  <testcase classname="com.obsqura.tests.CreateContact" name="CreateContactTest" time="4.145">
    <skipped/>
  </testcase> <!-- CreateContactTest -->
  <testcase classname="com.obsqura.tests.CreateContact" name="CreateContactTest" time="4.018">
    <failure type="java.lang.AssertionError" message="expected [Contact Updated Successfully] but found [×
Alert!
Contact Updated Successfully]">
      <![CDATA[java.lang.AssertionError: expected [Contact Updated Successfully] but found [×
Alert!
Contact Updated Successfully]
at com.obsqura.tests.CreateContact.CreateContactTest(CreateContact.java:25)
at java.base/java.util.ArrayList.forEach(ArrayList.java:1511)
at java.base/java.util.concurrent.FutureTask.run(FutureTask.java:264)
at java.base/java.util.concurrent.ThreadPoolExecutor.runWorker(ThreadPoolExecutor.java:1136)
at java.base/java.util.concurrent.ThreadPoolExecutor$Worker.run(ThreadPoolExecutor.java:635)
at java.base/java.lang.Thread.run(Thread.java:833)
... Removed 23 stack frames]]>
    </failure>
  </testcase> <!-- CreateContactTest -->
</testsuite> <!-- Test8 -->
